Workbook

Sheet raw_data
A1: key_resp.keys | B1: key_resp.corr | C1: tilt
A2: up | B2: 1 | C2: 0
A3: up | B3: 1 | C3: 0
A4: down | B4: 1 | C4: 2
A5: down | B5: 1 | C5: -2
A6: up | B6: 1 | C6: 0
A7: down | B7: 0 | C7: 0
A8: up | B8: 1 | C8: 0
A9: up | B9: 1 | C9: 0
A10: down | B10: 0 | C10: 0
A11: up | B11: 0 | C11: 1
A12: down | B12: 0 | C12: 0
A13: down | B13: 0 | C13: 0
... A101: up | B101: 1 | C101: 0

Sheet analysis
A1: Trial | B1: key_resp.keys | C1: key_resp.corr | D1: tilt | E1: Hit | F1: Miss | G1: False Alarm | H1: Correct Rejection | I1: Correct (Hit or CR) | J1: SDT 2x2 outcome table
A2: =ROW()-1 -> 1 | B2: =raw_data!A2 -> up | C2: =raw_data!B2 -> 1 | D2: =raw_data!C2 -> 0 | E2: =IF(AND(D2=0,B2="up"),1,0) -> 1 | F2: =IF(AND(D2=0,B2="down"),1,0) -> 0 | G2: =IF(AND(D2<>0,B2="up"),1,0) -> 0 | H2: =IF(AND(D2<>0,B2="down"),1,0) -> 0 | I2: =E2+H2 -> 1
A3: =ROW()-1 -> 2 | B3: =raw_data!A3 -> up | C3: =raw_data!B3 -> 1 | D3: =raw_data!C3 -> 0 | E3: =IF(AND(D3=0,B3="up"),1,0) -> 1 | F3: =IF(AND(D3=0,B3="down"),1,0) -> 0 | G3: =IF(AND(D3<>0,B3="up"),1,0) -> 0 | H3: =IF(AND(D3<>0,B3="down"),1,0) -> 0 | I3: =E3+H3 -> 1 | K3: Respond YES | L3: Respond NO
A4: =ROW()-1 -> 3 | B4: =raw_data!A4 -> down | C4: =raw_data!B4 -> 1 | D4: =raw_data!C4 -> 2 | E4: =IF(AND(D4=0,B4="up"),1,0) -> 0 | F4: =IF(AND(D4=0,B4="down"),1,0) -> 0 | G4: =IF(AND(D4<>0,B4="up"),1,0) -> 0 | H4: =IF(AND(D4<>0,B4="down"),1,0) -> 1 | I4: =E4+H4 -> 1 | J4: Signal present (tilt = 0) | K4: =SUM(E2:E101) -> 36 | L4: =SUM(F2:F101) -> 19
A5: =ROW()-1 -> 4 | B5: =raw_data!A5 -> down | C5: =raw_data!B5 -> 1 | D5: =raw_data!C5 -> -2 | E5: =IF(AND(D5=0,B5="up"),1,0) -> 0 | F5: =IF(AND(D5=0,B5="down"),1,0) -> 0 | G5: =IF(AND(D5<>0,B5="up"),1,0) -> 0 | H5: =IF(AND(D5<>0,B5="down"),1,0) -> 1 | I5: =E5+H5 -> 1 | J5: Signal absent (tilt <> 0) | K5: =SUM(G2:G101) -> 25 | L5: =SUM(H2:H101) -> 20
A6: =ROW()-1 -> 5 | B6: =raw_data!A6 -> up | C6: =raw_data!B6 -> 1 | D6: =raw_data!C6 -> 0 | E6: =IF(AND(D6=0,B6="up"),1,0) -> 1 | F6: =IF(AND(D6=0,B6="down"),1,0) -> 0 | G6: =IF(AND(D6<>0,B6="up"),1,0) -> 0 | H6: =IF(AND(D6<>0,B6="down"),1,0) -> 0 | I6: =E6+H6 -> 1
A7: =ROW()-1 -> 6 | B7: =raw_data!A7 -> down | C7: =raw_data!B7 -> 0 | D7: =raw_data!C7 -> 0 | E7: =IF(AND(D7=0,B7="up"),1,0) -> 0 | F7: =IF(AND(D7=0,B7="down"),1,0) -> 1 | G7: =IF(AND(D7<>0,B7="up"),1,0) -> 0 | H7: =IF(AND(D7<>0,B7="down"),1,0) -> 0 | I7: =E7+H7 -> 0 | J7: Hit | K7: =K4 -> 36
A8: =ROW()-1 -> 7 | B8: =raw_data!A8 -> up | C8: =raw_data!B8 -> 1 | D8: =raw_data!C8 -> 0 | E8: =IF(AND(D8=0,B8="up"),1,0) -> 1 | F8: =IF(AND(D8=0,B8="down"),1,0) -> 0 | G8: =IF(AND(D8<>0,B8="up"),1,0) -> 0 | H8: =IF(AND(D8<>0,B8="down"),1,0) -> 0 | I8: =E8+H8 -> 1 | J8: Miss | K8: =L4 -> 19
A9: =ROW()-1 -> 8 | B9: =raw_data!A9 -> up | C9: =raw_data!B9 -> 1 | D9: =raw_data!C9 -> 0 | E9: =IF(AND(D9=0,B9="up"),1,0) -> 1 | F9: =IF(AND(D9=0,B9="down"),1,0) -> 0 | G9: =IF(AND(D9<>0,B9="up"),1,0) -> 0 | H9: =IF(AND(D9<>0,B9="down"),1,0) -> 0 | I9: =E9+H9 -> 1 | J9: False Alarm | K9: =K5 -> 25
A10: =ROW()-1 -> 9 | B10: =raw_data!A10 -> down | C10: =raw_data!B10 -> 0 | D10: =raw_data!C10 -> 0 | E10: =IF(AND(D10=0,B10="up"),1,0) -> 0 | F10: =IF(AND(D10=0,B10="down"),1,0) -> 1 | G10: =IF(AND(D10<>0,B10="up"),1,0) -> 0 | H10: =IF(AND(D10<>0,B10="down"),1,0) -> 0 | I10: =E10+H10 -> 0 | J10: Correct Rejection | K10: =L5 -> 20
A11: =ROW()-1 -> 10 | B11: =raw_data!A11 -> up | C11: =raw_data!B11 -> 0 | D11: =raw_data!C11 -> 1 | E11: =IF(AND(D11=0,B11="up"),1,0) -> 0 | F11: =IF(AND(D11=0,B11="down"),1,0) -> 0 | G11: =IF(AND(D11<>0,B11="up"),1,0) -> 1 | H11: =IF(AND(D11<>0,B11="down"),1,0) -> 0 | I11: =E11+H11 -> 0
A12: =ROW()-1 -> 11 | B12: =raw_data!A12 -> down | C12: =raw_data!B12 -> 0 | D12: =raw_data!C12 -> 0 | E12: =IF(AND(D12=0,B12="up"),1,0) -> 0 | F12: =IF(AND(D12=0,B12="down"),1,0) -> 1 | G12: =IF(AND(D12<>0,B12="up"),1,0) -> 0 | H12: =IF(AND(D12<>0,B12="down"),1,0) -> 0 | I12: =E12+H12 -> 0 | J12: Response Yes (Hit+FA) | K12: =K7+K9 -> 61
A13: =ROW()-1 -> 12 | B13: =raw_data!A13 -> down | C13: =raw_data!B13 -> 0 | D13: =raw_data!C13 -> 0 | E13: =IF(AND(D13=0,B13="up"),1,0) -> 0 | F13: =IF(AND(D13=0,B13="down"),1,0) -> 1 | G13: =IF(AND(D13<>0,B13="up"),1,0) -> 0 | H13: =IF(AND(D13<>0,B13="down"),1,0) -> 0 | I13: =E13+H13 -> 0 | J13: Response No (Miss+CR) | K13: =K8+K10 -> 39
A14: =ROW()-1 -> 13 | B14: =raw_data!A14 -> down | C14: =raw_data!B14 -> 1 | D14: =raw_data!C14 -> 3 | E14: =IF(AND(D14=0,B14="up"),1,0) -> 0 | F14: =IF(AND(D14=0,B14="down"),1,0) -> 0 | G14: =IF(AND(D14<>0,B14="up"),1,0) -> 0 | H14: =IF(AND(D14<>0,B14="down"),1,0) -> 1 | I14: =E14+H14 -> 1
A15: =ROW()-1 -> 14 | B15: =raw_data!A15 -> down | C15: =raw_data!B15 -> 1 | D15: =raw_data!C15 -> 4 | E15: =IF(AND(D15=0,B15="up"),1,0) -> 0 | F15: =IF(AND(D15=0,B15="down"),1,0) -> 0 | G15: =IF(AND(D15<>0,B15="up"),1,0) -> 0 | H15: =IF(AND(D15<>0,B15="down"),1,0) -> 1 | I15: =E15+H15 -> 1 | J15: prop hit = hit / (hit + miss) | K15: =K7/(K7+K8) -> 0.65454545
A16: =ROW()-1 -> 15 | B16: =raw_data!A16 -> down | C16: =raw_data!B16 -> 1 | D16: =raw_data!C16 -> -1 | E16: =IF(AND(D16=0,B16="up"),1,0) -> 0 | F16: =IF(AND(D16=0,B16="down"),1,0) -> 0 | G16: =IF(AND(D16<>0,B16="up"),1,0) -> 0 | H16: =IF(AND(D16<>0,B16="down"),1,0) -> 1 | I16: =E16+H16 -> 1 | J16: prop fa = fa / (fa + correct rejection) | K16: =K9/(K9+K10) -> 0.55555556
A17: =ROW()-1 -> 16 | B17: =raw_data!A17 -> down | C17: =raw_data!B17 -> 1 | D17: =raw_data!C17 -> 1 | E17: =IF(AND(D17=0,B17="up"),1,0) -> 0 | F17: =IF(AND(D17=0,B17="down"),1,0) -> 0 | G17: =IF(AND(D17<>0,B17="up"),1,0) -> 0 | H17: =IF(AND(D17<>0,B17="down"),1,0) -> 1 | I17: =E17+H17 -> 1
A18: =ROW()-1 -> 17 | B18: =raw_data!A18 -> down | C18: =raw_data!B18 -> 0 | D18: =raw_data!C18 -> 0 | E18: =IF(AND(D18=0,B18="up"),1,0) -> 0 | F18: =IF(AND(D18=0,B18="down"),1,0) -> 1 | G18: =IF(AND(D18<>0,B18="up"),1,0) -> 0 | H18: =IF(AND(D18<>0,B18="down"),1,0) -> 0 | I18: =E18+H18 -> 0 | J18: z(prop hit) | K18: =_xlfn.NORM.S.INV(K15) -> 0.39762166
A19: =ROW()-1 -> 18 | B19: =raw_data!A19 -> down | C19: =raw_data!B19 -> 1 | D19: =raw_data!C19 -> -5 | E19: =IF(AND(D19=0,B19="up"),1,0) -> 0 | F19: =IF(AND(D19=0,B19="down"),1,0) -> 0 | G19: =IF(AND(D19<>0,B19="up"),1,0) -> 0 | H19: =IF(AND(D19<>0,B19="down"),1,0) -> 1 | I19: =E19+H19 -> 1 | J19: z(prop fa) | K19: =_xlfn.NORM.S.INV(K16) -> 0.1397103
A20: =ROW()-1 -> 19 | B20: =raw_data!A20 -> up | C20: =raw_data!B20 -> 0 | D20: =raw_data!C20 -> 2 | E20: =IF(AND(D20=0,B20="up"),1,0) -> 0 | F20: =IF(AND(D20=0,B20="down"),1,0) -> 0 | G20: =IF(AND(D20<>0,B20="up"),1,0) -> 1 | H20: =IF(AND(D20<>0,B20="down"),1,0) -> 0 | I20: =E20+H20 -> 0
A21: =ROW()-1 -> 20 | B21: =raw_data!A21 -> up | C21: =raw_data!B21 -> 0 | D21: =raw_data!C21 -> 0 | E21: =IF(AND(D21=0,B21="up"),1,0) -> 1 | F21: =IF(AND(D21=0,B21="down"),1,0) -> 0 | G21: =IF(AND(D21<>0,B21="up"),1,0) -> 0 | H21: =IF(AND(D21<>0,B21="down"),1,0) -> 0 | I21: =E21+H21 -> 1 | J21: d' = z(prop hit) - z(prop fa) | K21: =K18-K19 -> 0.25791136
A22: =ROW()-1 -> 21 | B22: =raw_data!A22 -> up | C22: =raw_data!B22 -> 0 | D22: =raw_data!C22 -> 1 | E22: =IF(AND(D22=0,B22="up"),1,0) -> 0 | F22: =IF(AND(D22=0,B22="down"),1,0) -> 0 | G22: =IF(AND(D22<>0,B22="up"),1,0) -> 1 | H22: =IF(AND(D22<>0,B22="down"),1,0) -> 0 | I22: =E22+H22 -> 0 | J22: c = -[z(prop hit) + z(prop fa)] / 2 | K22: =-(K18+K19)/2 -> -0.26866598
A23: =ROW()-1 -> 22 | B23: =raw_data!A23 -> up | C23: =raw_data!B23 -> 1 | D23: =raw_data!C23 -> 0 | E23: =IF(AND(D23=0,B23="up"),1,0) -> 1 | F23: =IF(AND(D23=0,B23="down"),1,0) -> 0 | G23: =IF(AND(D23<>0,B23="up"),1,0) -> 0 | H23: =IF(AND(D23<>0,B23="down"),1,0) -> 0 | I23: =E23+H23 -> 1
A24: =ROW()-1 -> 23 | B24: =raw_data!A24 -> up | C24: =raw_data!B24 -> 0 | D24: =raw_data!C24 -> 1 | E24: =IF(AND(D24=0,B24="up"),1,0) -> 0 | F24: =IF(AND(D24=0,B24="down"),1,0) -> 0 | G24: =IF(AND(D24<>0,B24="up"),1,0) -> 1 | H24: =IF(AND(D24<>0,B24="down"),1,0) -> 0 | I24: =E24+H24 -> 0
A25: =ROW()-1 -> 24 | B25: =raw_data!A25 -> down | C25: =raw_data!B25 -> 1 | D25: =raw_data!C25 -> -5 | E25: =IF(AND(D25=0,B25="up"),1,0) -> 0 | F25: =IF(AND(D25=0,B25="down"),1,0) -> 0 | G25: =IF(AND(D25<>0,B25="up"),1,0) -> 0 | H25: =IF(AND(D25<>0,B25="down"),1,0) -> 1 | I25: =E25+H25 -> 1 | J25: Outcome | K25: Count
A26: =ROW()-1 -> 25 | B26: =raw_data!A26 -> up | C26: =raw_data!B26 -> 0 | D26: =raw_data!C26 -> 3 | E26: =IF(AND(D26=0,B26="up"),1,0) -> 0 | F26: =IF(AND(D26=0,B26="down"),1,0) -> 0 | G26: =IF(AND(D26<>0,B26="up"),1,0) -> 1 | H26: =IF(AND(D26<>0,B26="down"),1,0) -> 0 | I26: =E26+H26 -> 0 | J26: Hit | K26: =K7 -> 36
A27: =ROW()-1 -> 26 | B27: =raw_data!A27 -> down | C27: =raw_data!B27 -> 0 | D27: =raw_data!C27 -> 0 | E27: =IF(AND(D27=0,B27="up"),1,0) -> 0 | F27: =IF(AND(D27=0,B27="down"),1,0) -> 1 | G27: =IF(AND(D27<>0,B27="up"),1,0) -> 0 | H27: =IF(AND(D27<>0,B27="down"),1,0) -> 0 | I27: =E27+H27 -> 0 | J27: Miss | K27: =K8 -> 19
A28: =ROW()-1 -> 27 | B28: =raw_data!A28 -> down | C28: =raw_data!B28 -> 0 | D28: =raw_data!C28 -> 0 | E28: =IF(AND(D28=0,B28="up"),1,0) -> 0 | F28: =IF(AND(D28=0,B28="down"),1,0) -> 1 | G28: =IF(AND(D28<>0,B28="up"),1,0) -> 0 | H28: =IF(AND(D28<>0,B28="down"),1,0) -> 0 | I28: =E28+H28 -> 0 | J28: False Alarm | K28: =K9 -> 25
A29: =ROW()-1 -> 28 | B29: =raw_data!A29 -> down | C29: =raw_data!B29 -> 1 | D29: =raw_data!C29 -> -3 | E29: =IF(AND(D29=0,B29="up"),1,0) -> 0 | F29: =IF(AND(D29=0,B29="down"),1,0) -> 0 | G29: =IF(AND(D29<>0,B29="up"),1,0) -> 0 | H29: =IF(AND(D29<>0,B29="down"),1,0) -> 1 | I29: =E29+H29 -> 1 | J29: Correct Rejection | K29: =K10 -> 20
A30: =ROW()-1 -> 29 | B30: =raw_data!A30 -> down | C30: =raw_data!B30 -> 1 | D30: =raw_data!C30 -> 2 | E30: =IF(AND(D30=0,B30="up"),1,0) -> 0 | F30: =IF(AND(D30=0,B30="down"),1,0) -> 0 | G30: =IF(AND(D30<>0,B30="up"),1,0) -> 0 | H30: =IF(AND(D30<>0,B30="down"),1,0) -> 1 | I30: =E30+H30 -> 1
A31: =ROW()-1 -> 30 | B31: =raw_data!A31 -> down | C31: =raw_data!B31 -> 0 | D31: =raw_data!C31 -> 0 | E31: =IF(AND(D31=0,B31="up"),1,0) -> 0 | F31: =IF(AND(D31=0,B31="down"),1,0) -> 1 | G31: =IF(AND(D31<>0,B31="up"),1,0) -> 0 | H31: =IF(AND(D31<>0,B31="down"),1,0) -> 0 | I31: =E31+H31 -> 0
A32: =ROW()-1 -> 31 | B32: =raw_data!A32 -> down | C32: =raw_data!B32 -> 0 | D32: =raw_data!C32 -> 0 | E32: =IF(AND(D32=0,B32="up"),1,0) -> 0 | F32: =IF(AND(D32=0,B32="down"),1,0) -> 1 | G32: =IF(AND(D32<>0,B32="up"),1,0) -> 0 | H32: =IF(AND(D32<>0,B32="down"),1,0) -> 0 | I32: =E32+H32 -> 0
A33: =ROW()-1 -> 32 | B33: =raw_data!A33 -> down | C33: =raw_data!B33 -> 1 | D33: =raw_data!C33 -> 0 | E33: =IF(AND(D33=0,B33="up"),1,0) -> 0 | F33: =IF(AND(D33=0,B33="down"),1,0) -> 1 | G33: =IF(AND(D33<>0,B33="up"),1,0) -> 0 | H33: =IF(AND(D33<>0,B33="down"),1,0) -> 0 | I33: =E33+H33 -> 0
A34: =ROW()-1 -> 33 | B34: =raw_data!A34 -> down | C34: =raw_data!B34 -> 1 | D34: =raw_data!C34 -> 1 | E34: =IF(AND(D34=0,B34="up"),1,0) -> 0 | F34: =IF(AND(D34=0,B34="down"),1,0) -> 0 | G34: =IF(AND(D34<>0,B34="up"),1,0) -> 0 | H34: =IF(AND(D34<>0,B34="down"),1,0) -> 1 | I34: =E34+H34 -> 1
A35: =ROW()-1 -> 34 | B35: =raw_data!A35 -> down | C35: =raw_data!B35 -> 0 | D35: =raw_data!C35 -> 0 | E35: =IF(AND(D35=0,B35="up"),1,0) -> 0 | F35: =IF(AND(D35=0,B35="down"),1,0) -> 1 | G35: =IF(AND(D35<>0,B35="up"),1,0) -> 0 | H35: =IF(AND(D35<>0,B35="down"),1,0) -> 0 | I35: =E35+H35 -> 0
A36: =ROW()-1 -> 35 | B36: =raw_data!A36 -> down | C36: =raw_data!B36 -> 0 | D36: =raw_data!C36 -> 0 | E36: =IF(AND(D36=0,B36="up"),1,0) -> 0 | F36: =IF(AND(D36=0,B36="down"),1,0) -> 1 | G36: =IF(AND(D36<>0,B36="up"),1,0) -> 0 | H36: =IF(AND(D36<>0,B36="down"),1,0) -> 0 | I36: =E36+H36 -> 0
A37: =ROW()-1 -> 36 | B37: =raw_data!A37 -> down | C37: =raw_data!B37 -> 1 | D37: =raw_data!C37 -> -2 | E37: =IF(AND(D37=0,B37="up"),1,0) -> 0 | F37: =IF(AND(D37=0,B37="down"),1,0) -> 0 | G37: =IF(AND(D37<>0,B37="up"),1,0) -> 0 | H37: =IF(AND(D37<>0,B37="down"),1,0) -> 1 | I37: =E37+H37 -> 1
A38: =ROW()-1 -> 37 | B38: =raw_data!A38 -> down | C38: =raw_data!B38 -> 1 | D38: =raw_data!C38 -> -4 | E38: =IF(AND(D38=0,B38="up"),1,0) -> 0 | F38: =IF(AND(D38=0,B38="down"),1,0) -> 0 | G38: =IF(AND(D38<>0,B38="up"),1,0) -> 0 | H38: =IF(AND(D38<>0,B38="down"),1,0) -> 1 | I38: =E38+H38 -> 1
A39: =ROW()-1 -> 38 | B39: =raw_data!A39 -> up | C39: =raw_data!B39 -> 0 | D39: =raw_data!C39 -> -5 | E39: =IF(AND(D39=0,B39="up"),1,0) -> 0 | F39: =IF(AND(D39=0,B39="down"),1,0) -> 0 | G39: =IF(AND(D39<>0,B39="up"),1,0) -> 1 | H39: =IF(AND(D39<>0,B39="down"),1,0) -> 0 | I39: =E39+H39 -> 0
A40: =ROW()-1 -> 39 | B40: =raw_data!A40 -> up | C40: =raw_data!B40 -> 0 | D40: =raw_data!C40 -> -5 | E40: =IF(AND(D40=0,B40="up"),1,0) -> 0 | F40: =IF(AND(D40=0,B40="down"),1,0) -> 0 | G40: =IF(AND(D40<>0,B40="up"),1,0) -> 1 | H40: =IF(AND(D40<>0,B40="down"),1,0) -> 0 | I40: =E40+H40 -> 0
...
